Workbook

Sheet Copyright
B2: Value Driver Modelling
B3: Example Value Driver Trees
B4: Copyright
B9: This work is licensed under a Creative Commons Attribution-NonCommercial-ShareAlike 4.0 International License

Sheet V2-Benefit
C2: =Copyright!B2 -> Value Driver Modelling
C3: =Copyright!B3 -> Example Value Driver Trees
C4: Benefits Realisation VDT
B6: Benefit Dependency Network
B21: Value Driver Tree
C23: Increase revenue from accurate timesheets ($) | F23: Increased hours from recording at least planned capacity (hrs) | I23: FTEs charging less than planned capacity (#)
C24: =PRODUCT(F24,F45) -> 1875000 | F24: =PRODUCT(I24,I27,I30) -> 1250 | I24: 50
D25: X | G25: X
I26: Days worked per year (#)
I27: 200
C28: Legend | G28: X
C29: Assumption | I29: Additional hours per resource day
C30: Investment Objective | I30: =L33*L42 -> 0.125
C31: Business Benefit
L32: Gap from planned capacity
L33: =O36-O39 -> 0.5
J34: X
O35: Planned hours (hrs)
O36: 8
M37: -
O38: Chargeable hours
O39: 7.5
L41: % of improvement
L42: 0.25
F44: Recoverable Chargeable Rate ($/hr) | I44: Average Chargeout Rate ($/hr)
F45: =PRODUCT(I45,I48) -> 1500 | I45: 2000
G46: X
I47: % of increase that is chargeable
I48: 0.75

Sheet V2-Revenue
C2: =Copyright!B2 -> Value Driver Modelling
C3: =Copyright!B3 -> Example Value Driver Trees
C4: Revenue VDT
C8: Total Revenue ($USD) | F8: Average Price ($USD/L) | I8: Foregin Exchange (USD/AUD)
C9: =PRODUCT(F9,F15) -> 39098182 | F9: =I12/I9 -> 36.363636 | I9: 1.1
D10: X | G10: ÷
I11: Domestic Price ($AUD/L)
I12: 40
F14: Total Litres Constrained (L) | I14: Total Chemical Input Contrained (L) | L14: Total Litres produced from Consumable (L) | O14: Consumable (L)
F15: =MIN(I15,I27,I33) -> 1075200 | I15: =MIN(L15,L21) -> 1157863.2 | L15: =O15*O18 -> 1289883.2 | O15: 1612354
G16: Min | J16: Min | M16: x
O17: Litres Produced per Consumnable Litres (L/L)
O18: 0.8
C20: Legend | L20: Reagents ($) | O20: Reagents (L)
C21: Calculation | L21: =O21*O24 -> 1157863.2 | O21: 5789316
C22: Input | M22: x
O23: Litres Produced per Reagent Litres (L/L)
O24: 0.2
I26: Total Production Input (L) | L26: Operating Time (UtilHr)
I27: =L27*L30 -> 1081825 | L27: 1985
G28: Min | J28: X
L29: Litres per hour (L/hr)
L30: 545
I32: Total Labour (L) | L32: Total hours of work a year per person (hrs) | O32: Average days worked a year (#)
I33: =L33*L39*L42 -> 1075200 | L33: =O33*O36 -> 1920 | O33: 240
J34: X | M34: X
O35: Average shift (Hrs)
O36: 8
L38: Number of Employees (#)
L39: 14
J40: X
L41: Litres per hour (L/hr)
L42: 40

Sheet V2- Cost
C2: =Copyright!B2 -> Value Driver Modelling
C3: =Copyright!B3 -> Example Value Driver Trees
C4: Cost VDT
C8: Total Cost ($) | F8: Total Fixed Cost ($) | I8: Total External Services Cost ($)
C9: =SUM(L15,L21,I27,I36) -> 21995356 | F9: =SUM(I9,I12) -> 612562 | I9: 28000
D10: + | G10: +
I11: Total General & Admin Cost ($)
I12: 584562
F14: Total Variable Cost ($) | I14: Total Materials Cost ($) | L14: Consumables ($) | O14: Consumable (L)
F15: =SUM(I15,I27,I36) -> 21995356 | I15: =SUM(L15,L21) -> 17578632 | L15: =O15*O18 -> 6000000 | O15: 2000000
G16: + | J16: + | M16: X
O17: Cost per Consumable L ($/L)
O18: 3
C20: Legend | L20: Reagents ($) | O20: Reagents (L)
C21: Calculation | L21: =O21*O24 -> 11578632 | O21: 5789316
C22: Input | M22: X
O23: Cost per Reagent ($/L)
O24: 2
I26: Total Electricity Cost ($) | L26: Operating Time (UtilHr)
I27: =L27*L30 -> 250324.38 | L27: 1985
G28: + | J28: X
L29: Power Cost ($/UtilHr) | O29: Power Consumption (Kwh/UtilHr)
L30: =O30*O33 -> 126.108 | O30: 1695
M31: X
O32: Electricity Cost ($/Kwh)
O33: 0.0744
I35: Total Labour Cost ($) | L35: Total hours of work a year per person (hrs) | O35: Average days worked a year (#)
I36: =L36*L42*L45 -> 4166400 | L36: =O36*O39 -> 1920 | O36: 240
J37: X | M37: X
O38: Average shift (Hrs)
O39: 8
L41: No. of Employees (#)
L42: 14
J43: X
L44: Average cost per Employees ($/Hr)
L45: 155

Sheet V2-Profit
C2: =Copyright!B2 -> Value Driver Modelling
C3: =Copyright!B3 -> Example Value Driver Trees
C4: Profit VDT
C6: Gross Profit ($) | F6: Total Revenue ($) | I6: Average Price ($AUD/L) | L6: Foregin Exchange ($AUD/$USD)
C7: =F7-F43 -> 9065977 | F7: =PRODUCT(I7,I13) -> 31061333 | I7: =L10/L7 -> 28.888889 | L7: 0.9
D8: - | G8: X | J8: ÷
B9: Legend | L9: Domestic Price ($USD/L)
B10: Calculation | L10: 26
B11: Input
B12: Linked value | I12: Total Litres Constrained (L) | L12: Total Chemical Input Contrained (L) | O12: Total Litres produced from Consumable (L) | R12: Consumable (L)
I13: =MIN(L13,L25,L31) -> 1075200 | L13: =MIN(O13,O19) -> 1157863.2 | O13: =R13*R16 -> 1600000 | R13: 2000000
J14: Min | M14: Min | P14: x
R15: Litres Produced per Consumnable Litres (L/L)
R16: 0.8
O18: Reagents ($) | R18: Reagents (L)
O19: =R19*R22 -> 1157863.2 | R19: 5789316
P20: x
R21: Litres Produced per Reagent Litres (L/L)
R22: 0.2
L24: Total Production Input (L) | O24: Operating Time (UtilHr)
L25: =O25*O28 -> 1081825 | O25: 1985
J26: Min | M26: X
O27: Litres per hour (L/hr)
O28: 545
L30: Total Labour (L) | O30: Total hours of work a year per person (hrs) | R30: Average days worked a year (#)
L31: =O31*O37*O40 -> 1075200 | O31: =R31*R34 -> 1920 | R31: 240
M32: X | P32: X
R33: Average shift (Hrs)
R34: 8
O36: Number of Employees (#)
O37: 14
M38: X
O39: Litres per hour (L/hr)
O40: 40
F42: Total Cost ($) | I42: Total Fixed Cost ($) | L42: Total External Services Cost ($)
F43: =SUM(O49,O55,L61,L70) -> 21995356 | I43: =SUM(L43,L46) -> 612562 | L43: 28000
G44: + | J44: +
L45: Total General & Admin Cost ($)
L46: 584562
I48: Total Variable Cost ($) | L48: Total Materials Cost ($) | O48: Consumables ($) | R48: =R12 -> Consumable (L)
...

Sheet V2-Financial
C2: =Copyright!B2 -> Value Driver Modelling
C3: =Copyright!B3 -> Example Value Driver Trees
C4: Financial VDT
C6: Economic Value Added | F6: NOPAT | I6: Tax
C7: =F7-F19 -> 117000 | F7: =I7*I10 -> 225000 | I7: 0.3
D8: - | G8: X
I9: EBIT | L9: Contribution Margin | O9: Sales
I10: =L10-L16 -> 750000 | L10: =O10-O13 -> 1000000 | O10: 4000000
J11: - | M11: -
O12: Cost of Goods Sold
O13: 3000000
L15: Cost of Organisation
L16: 250000
F18: Cost of Capital | I18: WACC
F19: =I19*I23 -> 108000 | I19: 0.09
G20: X
I22: Net Assets | L22: Fixed Assets
I23: =SUM(L23,L26) -> 1200000 | L23: 900000
J24: +
L25: Current Assets
L26: 300000
F28: Name | I28: Definition | L28: Ratio
F29: Asset turnover | I29: sales / assets | L29: =O10/I23 -> 3.3333333
F30: Current asset turnover | I30: sales / current assets | L30: =O10/L26 -> 13.333333
F31: Fixed asset turnover | I31: sales / fixed assets | L31: =O10/L23 -> 4.4444444
F32: EBIT margin | I32: EBIT / sales | L32: =I10/O10 -> 0.1875
F33: Gross profit margin | I33: (sales – cost of goods sold) / sales | L33: =(O10-O13)/O10 -> 0.25
F34: ROA | I34: net income / assets | L34: =F7/I23 -> 0.1875

Sheet V2-Reporting
C1: =Copyright!B2 -> Value Driver Modelling
C2: =Copyright!B3 -> Example Value Driver Trees
C3: Reporting
C5: Total Labour Costs ($) | D5: Margaret Gold (CFO) | G5: Total hours of work a year per person (hrs) | H5: David O'Sullivan (HR) | K5: Average days worked a year (#) | L5: Matthew Wallace (Superintendent)
C6: Planned | D6: =PRODUCT(H6,H16,H21) -> 2976000 | G6: Planned | H6: =PRODUCT(L6,L11) -> 1920 | K6: Planned | L6: 240
C7: Actual | D7: =PRODUCT(H7,H17,H22) -> 2808000 | G7: Actual | H7: =PRODUCT(L7,L12) -> 2160 | K7: Actual | L7: 240
C8: Variance | D8: =(D7/D6)-1 -> -0.056451613 | G8: Variance | H8: =(H7/H6)-1 -> 0.125 | K8: Variance | L8: =(L7/L6)-1 -> 0
K10: Average shift (Hrs) | L10: Luke King (Supervisor)
K11: Planned | L11: 8
K12: Actual | L12: 9
K13: Variance | L13: =(L12/L11)-1 -> 0.125
G15: No. of Employees (#) | H15: David O'Sullivan (HR)
G16: Planned | H16: 10
G17: Actual | H17: 10
G18: Variance | H18: =(H17/H16)-1 -> 0
G20: Average cost per Employees ($/Hr) | H20: Susan Grace (IR)
G21: Planned | H21: 155
G22: Actual | H22: 130
G23: Variance | H23: =(H22/H21)-1 -> -0.16129032

Sheet V2-Table
C2: =Copyright!B2 -> Value Driver Modelling
C3: =Copyright!B3 -> Example Value Driver Trees
C4: Value Driver Table
E6: Units | G6: Year 0 | I6: Year 1 | K6: Year 2 | M6: Year 3 | O6: Year 4
C7: Parameter
C9: Cotton Gin Calendar Time (Hrs) | E9: 8760 | G9: 8760 | I9: 8760 | K9: 8760 | M9: 8760 | O9: 8760
C10: Cotton Gin Down Time Maintenance (Hrs) | E10: =SUM(E11:E13) -> 1474.2093 | G10: =SUM(G11:G13) -> 1474.2093 | I10: =SUM(I11:I13) -> 1474.2093 | K10: =SUM(K11:K13) -> 1474.2093 | M10: =SUM(M11:M13) -> 1474.2093 | O10: =SUM(O11:O13) -> 1474.2093
C11: Cotton Gin Scheduled Loss (Hrs) | E11: 475.92061 | G11: 475.92061 | I11: 475.92061 | K11: 475.92061 | M11: 475.92061 | O11: 475.92061
C12: Cotton Gin Unscheduled Loss Other (Hrs) | E12: 868.37992 | G12: 868.37992 | I12: 868.37992 | K12: 868.37992 | M12: 868.37992 | O12: 868.37992
C13: Cotton Gin Unscheduled Loss Failures (Hrs) | E13: 129.90876 | G13: 129.90876 | I13: 129.90876 | K13: 129.90876 | M13: 129.90876 | O13: 129.90876
C15: Cotton Gin Available Time (Hrs) | E15: =E9-E10 -> 7285.7907 | G15: =G9-G10 -> 7285.7907 | I15: =I9-I10 -> 7285.7907 | K15: =K9-K10 -> 7285.7907 | M15: =M9-M10 -> 7285.7907 | O15: =O9-O10 -> 7285.7907
C16: Cotton Gin No Scheduled Production (Hrs) | E16: 151.11784 | G16: 151.11784 | I16: 151.11784 | K16: 151.11784 | M16: 151.11784 | O16: 151.11784
C17: Cotton Gin Operating Standby (Hrs) | E17: 2389.1034 | G17: 2389.1034 | I17: 2389.1034 | K17: 2389.1034 | M17: 2389.1034 | O17: 2389.1034
C19: Cotton Gin Utilised Time (Hrs) | E19: =E15-SUM(E16:E17) -> 4745.5695 | G19: =G15-SUM(G16:G17) -> 4745.5695 | I19: =I15-SUM(I16:I17) -> 4745.5695 | K19: =K15-SUM(K16:K17) -> 4745.5695 | M19: =M15-SUM(M16:M17) -> 4745.5695 | O19: =O15-SUM(O16:O17) -> 4745.5695
C20: Cotton Gin Operating Delay (Hrs) | E20: 1092.7302 | G20: 1092.7302 | I20: 1092.7302 | K20: 1092.7302 | M20: 1092.7302 | O20: 1092.7302
C22: Cotton Gin Operating Time (Hrs) | E22: hrs | G22: =G19-G20 -> 3652.8393 | I22: =I19-I20 -> 3652.8393 | K22: =K19-K20 -> 3652.8393 | M22: =M19-M20 -> 3652.8393 | O22: =O19-O20 -> 3652.8393
C24: Average Metres per Hour | E24: m/hr | G24: 54 | I24: 54 | K24: 54 | M24: 54 | O24: 54
C25: Total Metres Rolled | E25: m | G25: =G22*G24 -> 197253.32 | I25: =I22*I24 -> 197253.32 | K25: =K22*K24 -> 197253.32 | M25: =M22*M24 -> 197253.32 | O25: =O22*O24 -> 197253.32
C27: Average Metres per Separations | E27: m/sep | G27: 25 | I27: 24 | K27: 23 | M27: 22 | O27: 21
C28: Number of Separations | E28: sep | G28: =G25/G27 -> 7890.1329 | I28: =I25/I27 -> 8218.8884 | K28: =K25/K27 -> 8576.2314 | M28: =M25/M27 -> 8966.0601 | O28: =O25/O27 -> 9393.0153
C30: Average Separations per Processed Tonne | E30: sep/t | G30: 300 | I30: 300 | K30: 300 | M30: 300 | O30: 300
C31: Amount of Processed Tonnes | E31: t | G31: =G28/G30 -> 26.300443 | I31: =I28/I30 -> 27.396295 | K31: =K28/K30 -> 28.587438 | M31: =M28/M30 -> 29.886867 | O31: =O28/O30 -> 31.310051
C33: Number of Cotton Gins | E33: # | G33: 10 | I33: 10 | K33: 10 | M33: 12 | O33: 12
C34: Total Processed Tonnes with Factory | E34: t | G34: =G31*G33 -> 263.00443 | I34: =I31*I33 -> 273.96295 | K34: =K31*K33 -> 285.87438 | M34: =M31*M33 -> 358.6424 | O34: =O31*O33 -> 375.72061
C36: Baseline | E36: t | G36: 263.00443 | I36: 273.96295 | K36: 314.46182 | M36: 358.6424 | O36: 375.72061
C37: Improvement | E37: t | G37: =G34-G36 -> 0 | I37: =I34-I36 -> 0 | K37: =K34-K36 -> -28.587438 | M37: =M34-M36 -> 0 | O37: =O34-O36 -> 0
C60: Value Driver Tree Version

Sheet V2-Longitudinal 
C1: =Copyright!B2 -> Value Driver Modelling
C2: =Copyright!B3 -> Example Value Driver Trees
C3: Longitudinal VDT
E5: J | F5: A | G5: S | H5: O | I5: N | J5: D | K5: J | L5: F | M5: M | N5: A | O5: M | P5: J
C6: Production | D6: Actual | E6: 1256 | F6: 1100 | G6: 1230 | H6: 1536 | I6: 1234 | J6: 1353 | K6: 1303 | L6: 960 | M6: 900 | N6: 680 | O6: 642 | P6: 1000
D7: Planned | E7: 1250 | F7: 1500 | G7: 1250 | H7: 1000 | I7: 1000 | J7: 1000 | K7: 1000 | L7: 900 | M7: 1000 | N7: 1250 | O7: 1250 | P7: 1500
C8: Variable Cost | D8: Actual | E8: 12 | F8: 12 | G8: 12 | H8: 13 | I8: 15 | J8: 13 | K8: 12 | L8: 11 | M8: 10 | N8: 10 | O8: 10 | P8: 10
D9: Planned | E9: 10 | F9: 10 | G9: 10 | H9: 10 | I9: 10 | J9: 9 | K9: 9 | L9: 9 | M9: 9 | N9: 9 | O9: 9 | P9: 9
C10: Total Variable Cost | D10: Actual | E10: =E8*E6 -> 15072 | F10: =F8*F6 -> 13200 | G10: =G8*G6 -> 14760 | H10: =H8*H6 -> 19968 | I10: =I8*I6 -> 18510 | J10: =J8*J6 -> 17589 | K10: =K8*K6 -> 15636 | L10: =L8*L6 -> 10560 | ... P10: =P8*P6 -> 10000
D11: Planned | E11: =E9*E7 -> 12500 | F11: =F9*F7 -> 15000 | G11: =G9*G7 -> 12500 | H11: =H9*H7 -> 10000 | I11: =I9*I7 -> 10000 | J11: =J9*J7 -> 9000 | K11: =K9*K7 -> 9000 | L11: =L9*L7 -> 8100 | ... P11: =P9*P7 -> 13500
C12: Fixed Cost | D12: Actual | E12: 5000 | F12: 5500 | G12: 5600 | H12: 5700 | I12: 5000 | J12: 3000 | K12: 3000 | L12: 3500 | M12: 3400 | N12: 3600 | O12: 3400 | P12: 3000
D13: Planned | E13: 4500 | F13: 4500 | G13: 4500 | H13: 4500 | I13: 4500 | J13: 4500 | K13: 5000 | L13: 5000 | M13: 5000 | N13: 5000 | O13: 5000 | P13: 4000
C14: Total Cost | D14: Actual | E14: =E10+E12 -> 20072 | F14: =F10+F12 -> 18700 | G14: =G10+G12 -> 20360 | H14: =H10+H12 -> 25668 | I14: =I10+I12 -> 23510 | J14: =J10+J12 -> 20589 | K14: =K10+K12 -> 18636 | L14: =L10+L12 -> 14060 | ... P14: =P10+P12 -> 13000
D15: Planned | E15: =E11+E13 -> 17000 | F15: =F11+F13 -> 19500 | G15: =G11+G13 -> 17000 | H15: =H11+H13 -> 14500 | I15: =I11+I13 -> 14500 | J15: =J11+J13 -> 13500 | K15: =K11+K13 -> 14000 | L15: =L11+L13 -> 13100 | ... P15: =P11+P13 -> 17500
